Traceback (most recent call last):
  File "manage.py", line 10, in <module>
    execute_from_command_line(sys.argv)
  File "/usr/lib/python2.6/site-packages/Django-1.6.5-py2.6.egg/django/core/management/__init__.py", line 399, in execute_from_command_line
    utility.execute()
  File "/usr/lib/python2.6/site-packages/Django-1.6.5-py2.6.egg/django/core/management/__init__.py", line 392, in execute
    self.fetch_command(subcommand).run_from_argv(self.argv)
  File "/usr/lib/python2.6/site-packages/Django-1.6.5-py2.6.egg/django/core/management/__init__.py", line 261, in fetch_command
    commands = get_commands()
  File "/usr/lib/python2.6/site-packages/Django-1.6.5-py2.6.egg/django/core/management/__init__.py", line 107, in get_commands
    apps = settings.INSTALLED_APPS
  File "/usr/lib/python2.6/site-packages/Django-1.6.5-py2.6.egg/django/conf/__init__.py", line 54, in __getattr__
    self._setup(name)
  File "/usr/lib/python2.6/site-packages/Django-1.6.5-py2.6.egg/django/conf/__init__.py", line 49, in _setup
    self._wrapped = Settings(settings_module)
  File "/usr/lib/python2.6/site-packages/Django-1.6.5-py2.6.egg/django/conf/__init__.py", line 132, in __init__
    % (self.SETTINGS_MODULE, e)
ImportError: Could not import settings 'squrid_log.settings' (Is it on sys.path? Is there an import error in the settings file?): No module named squrid_log.settings
